<mujoco>
    <body pos="0.011 0.008 -0.1">
        <body name="servo_horn_rl" pos="0.0136 -0.0055 0.1">
            <joint name="thigh_joint_rl" pos="0 0 0.0064" ref="0" damping="0.005" type="hinge" axis="1 0 0" armature="0.00065"/>
            <site name="thigh_link_rl" pos="0.000 0 0.0064" size="0.001" rgba=".8 .1 .8 0"/>
            <geom name="servo_horn_rl" type="mesh"  mesh="servo_link_l" conaffinity="0" pos="-0.0112 0.0015 0.0043" euler="90 0 0" rgba="1 0.423529 0.0392157 1"/>
            <geom name="servo_check_rl" type="cylinder" conaffinity="0"  fromto="0.002 0 0.0064 0.003 0 0.0064" size="0.0039" rgba=".9 .1 .1 0" />
            <body name="thigh_up_link_1_rl" pos="0 0 0.0182">
                <geom name="thigh_up_link_1_rl" type="cylinder" conaffinity="0"  fromto="-0.002 0 0 0.002 0 0" size="0.0025" rgba=".9 .1 .1 0" />
                <site name="thigh_up_point_1_rl" pos="0.000 0 0" size="0.001" rgba=".8 .1 .8 0"/>
            </body>
        </body>

        <body name="main_leg_rl" pos="0 0 0.1">
            <geom name="hip_box_rl" type="mesh" mesh="hip_l" conaffinity="0" pos="0 0.0004 0.0071" euler="90 0 0" rgba="0.6 0.6 0.6 0"/>
            <geom name="actuator_visual_top_rl" type="mesh" mesh="actuator_visual" mass="0.0" contype="0" conaffinity="0"
                pos="0.0027 -0.0016 0.01115" euler="0 0 -90" rgba="0.1 0.1 0.1 1"/>
            <geom name="actuator_visual_down_rl" type="mesh" mesh="actuator_visual" mass="0.0" contype="0" conaffinity="0"
                pos="0.0027 -0.0016 -0.00165" euler="0 0 -90" rgba="0.1 0.1 0.1 1"/>
            <geom name="actuator_frame_visual_rl" type="mesh" mesh="actuator_frame_visual" mass="0.0" contype="0" conaffinity="0"
                pos="-0.0015 -0.008 -0.00" euler="180 90 0" material="white_nylon"/>
            <body name="thigh_down_rl" pos="0.0136 -0.0055 -0.0064">
                <joint name="leg_joint_rl" pos="0 0 0" ref="0" damping="0.005" type="hinge" axis="1 0 0"  armature="0.00065"/>
                <site name="leg_link_rl" pos="0 0 0" size="0.003" rgba=".5 .5 .8 0"/>
                <geom name="thigh_down_rl" type="mesh" mesh="thigh_down_l" conaffinity="0" pos="-0.0044 0.05 0" euler="180 0 0" material="white_nylon"/>
                <geom name="servo_down_horn_rl_visual" type="mesh"  mesh="servo_link_l" mass="0.0" contype="0" conaffinity="0"
                 pos="-0.0111 -0.0021 -0.0015" euler="0 0 0" rgba="1 0.423529 0.0392157 1"/>

                <body name="foot_rl" pos="0 0.031 0" euler="-29.168 0 0">
                    <joint name="knee_down_rl" pos="0 0 0" type="hinge" axis="1 0 0" damping="0.005" armature="0.00065"/>
                    <site name="knee_down_rl" pos="0 0 0" size="0.001" rgba=".8 .1 .8 0"/>
                    <geom name="foot_rl" type="mesh" mesh="foot_l" pos="0.0036 0 -0.035"  euler="90 180 0" conaffinity="0" material="white_nylon"/>
                    <site name="ankle_rl" pos="0 0 -0.035" size="0.003" rgba=".8 .1 .8 0"/>
                    <!--add a site for foot contact detection -->
<!--                    <geom name="foot_placement_rl" mass= "0.00001" type="cylinder" fromto="-0.0044 0.0 -0.035 0.0016 0.0 -0.035" size="0.001" rgba=".8 .1 .1 0"/>-->
                    <!--add a site for foot touch sensor -->
                    <site name="foot_s_rl" type="cylinder" fromto="-0.0044 0.0 -0.035 0.0016 0.0 -0.035" size="0.004" rgba=".1 .1 .8 0"/>

                    <body name="thigh_up_rl" pos="0.00 0 0.015" euler="12.4566 0 0">
                        <joint name="knee_up_rl" pos="0 0 0" type="hinge" axis="1 0 0" damping="0.005" armature="0.00065"/>
                        <!--add a site for knee contact detection-->
                        <geom name="knee_rl_touch" mass= "0.00001" type="capsule" fromto="-0.0064 0.0 0 0.0036 0.0 0" size="0.00276" rgba=".8 .1 .1 0"/>
                        <site name="knee_up_rl" pos="0 0 0" size="0.001" rgba=".8 .1 .8 0"/>
                        <geom name="thigh_up_rl" type="mesh" mesh="thigh_up_l" conaffinity="0" pos="-0.0064 0.01 0" euler="90 0 0" material="white_nylon"/>
                        <body name="thigh_up_link_2_rl" pos="0 -0.040 0">
                            <geom name="thigh_up_link_2_rl" type="cylinder" conaffinity="0" mass=".001" fromto="-0.002 0 0 0.002 0 0" size="0.0025" rgba=".9 .9 .1 0" />
                            <site name="thigh_up_point_2_rl" pos="0.0 0 0" size="0.001" rgba=".8 .8 .1 0"/>
                        </body>
                    </body>
                    
                </body>
            </body>
        </body>
    </body>
</mujoco>
